<mujoco model="tidybot_push_hard">
  <compiler angle="radian" meshdir="tidybot/assets" autolimits="true"/>

  <option integrator="implicitfast"/>
  <option cone="elliptic" impratio="10"/>

  <default>
    <default class="base">
      <default class="base/visual">
        <geom type="mesh" contype="0" conaffinity="0" group="2"/>
      </default>
      <default class="base/collision">
        <geom type="box" group="3" contype="0" conaffinity="0"/>
      </default>
    </default>

    <default class="gen3">
      <default class="gen3/visual">
        <geom type="mesh" contype="0" conaffinity="0" group="2" rgba="0.75294 0.75294 0.75294 1"/>
      </default>
      <default class="gen3/collision">
        <geom type="capsule" group="3" contype="0" conaffinity="0"/>
      </default>
      <default class="large_actuator">
        <position kp="2000" kv="100" forcerange="-105 105"/>
      </default>
      <default class="small_actuator">
        <position kp="500" kv="50" forcerange="-52 52"/>
      </default>
    </default>

    <default class="2f85">
      <mesh scale="0.001 0.001 0.001"/>
      <general biastype="affine"/>
      <joint axis="1 0 0"/>
      <default class="driver">
        <joint range="0 0.8" armature="0.005" damping="0.1" solimplimit="0.95 0.99 0.001" solreflimit="0.005 1"/>
      </default>
      <default class="follower">
        <joint range="-0.872664 0.872664" armature="0.001" pos="0 -0.018 0.0065" solimplimit="0.95 0.99 0.001" solreflimit="0.005 1"/>
      </default>
      <default class="spring_link">
        <joint range="-0.29670597283 0.8" armature="0.001" stiffness="0.05" springref="2.62" damping="0.00125"/>
      </default>
      <default class="coupler">
        <joint range="-1.57 0" armature="0.001" solimplimit="0.95 0.99 0.001" solreflimit="0.005 1"/>
      </default>
      <default class="2f85/visual">
        <geom type="mesh" contype="0" conaffinity="0" group="2"/>
      </default>
      <default class="2f85/collision">
        <geom type="box" group="3" contype="0" conaffinity="0"/>
        <default class="pad_box1">
          <geom mass="0" type="box" pos="0 -0.0026 0.028125" size="0.011 0.004 0.009375" friction="0.7" solimp="0.95 0.99 0.001" solref="0.004 1" priority="1" rgba="0.55 0.55 0.55 1" contype="1" conaffinity="1"/>
        </default>
        <default class="pad_box2">
          <geom mass="0" type="box" pos="0 -0.0026 0.009375" size="0.011 0.004 0.009375" friction="0.6" solimp="0.95 0.99 0.001" solref="0.004 1" priority="1" rgba="0.45 0.45 0.45 1" contype="1" conaffinity="1"/>
        </default>
      </default>
    </default>
    <site size="0.001" rgba="0.5 0.5 0.5 0.3" group="4"/>
  </default>

  <asset>
    <material name="black" rgba="0.11372549 0.11372549 0.10196078 1"/>
    <material name="gray" rgba="0.62745098 0.65098039 0.64705882 1"/>
    <material name="dark_gray" rgba="0.35294118 0.37647059 0.37254902 1"/>
    <mesh file="base/bumper.stl"/>
    <mesh file="base/bottom_plate.stl"/>
    <mesh file="base/body.stl"/>
    <mesh file="base/top_plate.stl"/>
    <mesh file="base/arm_plate.stl"/>
    <mesh name="gen3/base_link" file="gen3/base_link.stl"/>
    <mesh name="shoulder_link" file="gen3/shoulder_link.stl"/>
    <mesh name="half_arm_1_link" file="gen3/half_arm_1_link.stl"/>
    <mesh name="half_arm_2_link" file="gen3/half_arm_2_link.stl"/>
    <mesh name="forearm_link" file="gen3/forearm_link.stl"/>
    <mesh name="spherical_wrist_1_link" file="gen3/spherical_wrist_1_link.stl"/>
    <mesh name="spherical_wrist_2_link" file="gen3/spherical_wrist_2_link.stl"/>
    <mesh name="bracelet_with_vision_link" file="gen3/bracelet_with_vision_link.stl"/>
    <material name="metal" rgba="0.58 0.58 0.58 1"/>
    <material name="silicone" rgba="0.1882 0.1882 0.1882 1"/>
    <material name="2f85/gray" rgba="0.4627 0.4627 0.4627 1"/>
    <material name="2f85/black" rgba="0.149 0.149 0.149 1"/>
    <mesh class="2f85" file="2f85/base.stl"/>
    <mesh class="2f85" file="2f85/driver.stl"/>
    <mesh class="2f85" file="2f85/coupler.stl"/>
    <mesh class="2f85" file="2f85/follower.stl"/>
    <mesh class="2f85" file="2f85/pad.stl"/>
    <mesh class="2f85" file="2f85/silicone_pad.stl"/>
    <mesh class="2f85" file="2f85/spring_link.stl"/>
  </asset>

  <worldbody>
    <light name="top" pos="0 0 2" mode="trackcom"/>

    <body name="base_link">
      <inertial pos="-0.000018 -0.000005 0.045575" mass="61.697" diaginertia="0.001 0.001 0.001"/>
      <joint name="joint_x" type="slide" axis="1 0 0"/>
      <joint name="joint_y" type="slide" axis="0 1 0"/>
      <joint name="joint_th"/>
      <geom class="base/visual" mesh="bumper" material="black"/>
      <geom class="base/visual" mesh="bottom_plate" material="dark_gray"/>
      <geom class="base/visual" mesh="body" material="gray"/>
      <geom class="base/visual" mesh="top_plate" material="dark_gray"/>
      <geom class="base/visual" mesh="arm_plate" material="gray"/>
      <geom class="base/collision" size="0.25 0.25 0.15" pos="0 0 0.1"/>

      <body name="gen3/base_link" pos="0 0 0.335" quat="1 0 0 0">
        <geom class="gen3/visual" mesh="gen3/base_link"/>
        <geom class="gen3/collision" type="cylinder" size="0.1 0.08"/>
        <body name="shoulder_link" pos="0 0 0.15643" quat="0 1 0 0">
          <inertial pos="-2.3e-05 -0.010364 -0.07336" quat="0.707051 0.0451246 -0.0453544 0.704263" mass="1.3773" diaginertia="0.00488868 0.00457 0.00135132"/>
          <joint name="joint_1"/>
          <geom class="gen3/visual" mesh="shoulder_link"/>
          <geom class="gen3/collision" type="cylinder" size="0.08 0.1"/>
          <body name="half_arm_1_link" pos="0 0.005375 -0.12838" quat="1 1 0 0">
            <joint name="joint_2" range="-2.24 2.24"/>
            <geom class="gen3/visual" mesh="half_arm_1_link"/>
            <geom class="gen3/collision" size="0.06 0.1"/>
            <body name="half_arm_2_link" pos="0 -0.21038 -0.006375" quat="1 -1 0 0">
              <joint name="joint_3"/>
              <geom class="gen3/visual" mesh="half_arm_2_link"/>
              <geom class="gen3/collision" size="0.06 0.1"/>
              <body name="forearm_link" pos="0 0.006375 -0.21038" quat="1 1 0 0">
                <joint name="joint_4" range="-2.57 2.57"/>
                <geom class="gen3/visual" mesh="forearm_link"/>
                <geom class="gen3/collision" size="0.05 0.1"/>
                <body name="spherical_wrist_1_link" pos="0 -0.20843 -0.006375" quat="1 -1 0 0">
                  <joint name="joint_5"/>
                  <geom class="gen3/visual" mesh="spherical_wrist_1_link"/>
                  <geom class="gen3/collision" type="sphere" size="0.05"/>
                  <body name="spherical_wrist_2_link" pos="0 0.00017505 -0.10593" quat="1 1 0 0">
                    <joint name="joint_6" range="-2.09 2.09"/>
                    <geom class="gen3/visual" mesh="spherical_wrist_2_link"/>
                    <geom class="gen3/collision" type="sphere" size="0.05"/>
                    <body name="bracelet_link" pos="0 -0.10593 -0.00017505" quat="1 -1 0 0">
                      <joint name="joint_7"/>
                      <geom class="gen3/visual" mesh="bracelet_with_vision_link"/>
                      <geom class="gen3/collision" size="0.04 0.05"/>
                      <body name="gripper_base" pos="0 0 -0.06149039" quat="0 -1 1 0" childclass="2f85">
                        <geom class="2f85/visual" mesh="base" material="2f85/black"/>
                        <geom class="2f85/collision" size="0.04 0.04 0.04"/>
                        <body name="right_driver" pos="0 0.0306011 0.054904">
                          <joint name="right_driver_joint" class="driver"/>
                          <geom class="2f85/visual" mesh="driver" material="2f85/gray"/>
                          <geom class="2f85/collision" size="0.005 0.02 0.02"/>
                          <body name="right_coupler" pos="0 0.0315 -0.0041">
                            <joint name="right_coupler_joint" class="coupler"/>
                            <geom class="2f85/visual" mesh="coupler" material="2f85/black"/>
                            <geom class="2f85/collision" size="0.01 0.01 0.01"/>
                          </body>
                        </body>
                        <body name="right_spring_link" pos="0 0.0132 0.0609">
                          <joint name="right_spring_link_joint" class="spring_link"/>
                          <geom class="2f85/visual" mesh="spring_link" material="2f85/black"/>
                          <geom class="2f85/collision" size="0.005 0.02 0.02"/>
                          <body name="right_follower" pos="0 0.055 0.0375">
                            <joint name="right_follower_joint" class="follower"/>
                            <geom class="2f85/visual" mesh="follower" material="2f85/black"/>
                            <geom class="2f85/collision" size="0.005 0.02 0.02"/>
                            <body name="right_pad" pos="0 -0.0189 0.01352">
                              <geom class="pad_box1" name="right_pad1"/>
                              <geom class="pad_box2" name="right_pad2"/>
                              <geom class="2f85/visual" mesh="pad"/>
                            </body>
                          </body>
                        </body>
                        <body name="left_driver" pos="0 -0.0306011 0.054904" quat="0 0 0 1">
                          <joint name="left_driver_joint" class="driver"/>
                          <geom class="2f85/visual" mesh="driver" material="2f85/gray"/>
                          <geom class="2f85/collision" size="0.005 0.02 0.02"/>
                          <body name="left_coupler" pos="0 0.0315 -0.0041">
                            <joint name="left_coupler_joint" class="coupler"/>
                            <geom class="2f85/visual" mesh="coupler" material="2f85/black"/>
                            <geom class="2f85/collision" size="0.01 0.01 0.01"/>
                          </body>
                        </body>
                        <body name="left_spring_link" pos="0 -0.0132 0.0609" quat="0 0 0 1">
                          <joint name="left_spring_link_joint" class="spring_link"/>
                          <geom class="2f85/visual" mesh="spring_link" material="2f85/black"/>
                          <geom class="2f85/collision" size="0.005 0.02 0.02"/>
                          <body name="left_follower" pos="0 0.055 0.0375">
                            <joint name="left_follower_joint" class="follower"/>
                            <geom class="2f85/visual" mesh="follower" material="2f85/black"/>
                            <geom class="2f85/collision" size="0.005 0.02 0.02"/>
                            <body name="left_pad" pos="0 -0.0189 0.01352">
                              <geom class="pad_box1" name="left_pad1"/>
                              <geom class="pad_box2" name="left_pad2"/>
                              <geom class="2f85/visual" mesh="pad"/>
                            </body>
                          </body>
                        </body>
                      </body>
                    </body>
                  </body>
                </body>
              </body>
            </body>
          </body>
        </body>
      </body>
    </body>

    <body name="binA" pos="-0.25 0.65 0">
      <geom name="binA_floor" pos="0 0 0.0005" size="0.25 0.25 0.0005" type="box" rgba="0 0.2 0.8 1" contype="0" conaffinity="0"/>
    </body>
    <body name="binB" pos="0.25 0.65 0">
      <geom name="binB_floor" pos="0 0 0.0005" size="0.25 0.25 0.0005" type="box" rgba="0.8 0 0 1" contype="0" conaffinity="0"/>
    </body>
    
    <body name="cube" pos="-0.25 0.65 0.07">
      <freejoint/>
      <geom name="cube_geom" size="0.03 0.03 0.03" type="box" rgba="0 0.4 0 1" contype="1" conaffinity="1"/>
    </body>
      
    <body name="goal_marker" pos="-0.25 0.65 0.07" gravcomp="1">
      <freejoint/>
      <geom name="goal_marker_geom" size="0.03 0.03 0.03" type="box" rgba="0.3 1 0.3 1" contype="0" conaffinity="0"/>
    </body>
      
    <body name="tablelink" pos="0 .2 0">
        <geom name="table_geom" group="4" pos="0.0 0.0 0.0" size="2.8 2.4 0.1" type="plane" mass="10" friction="0.2 0.005 0.0001" contype="1" conaffinity="1"/>
    </body>
  </worldbody>

  <contact>
    <exclude body1="bracelet_link" body2="left_driver"/>
    <exclude body1="bracelet_link" body2="right_driver"/>
    <exclude body1="bracelet_link" body2="left_spring_link"/>
    <exclude body1="bracelet_link" body2="right_spring_link"/>
    <exclude body1="right_coupler" body2="right_follower"/>
    <exclude body1="left_coupler" body2="left_follower"/>
    
    <pair geom1="cube_geom" geom2="table_geom"/>
    <pair geom1="cube_geom" geom2="left_pad1"/>
    <pair geom1="cube_geom" geom2="left_pad2"/>
    <pair geom1="cube_geom" geom2="right_pad1"/>
    <pair geom1="cube_geom" geom2="right_pad2"/>
    <pair geom1="table_geom" geom2="left_pad1"/>
    <pair geom1="table_geom" geom2="right_pad1"/>
  </contact>

  <tendon>
    <fixed name="split">
      <joint joint="right_driver_joint" coef="0.5"/>
      <joint joint="left_driver_joint" coef="0.5"/>
    </fixed>
  </tendon>

  <equality>
    <connect anchor="0 0 0" body1="right_follower" body2="right_coupler" solimp="0.95 0.99 0.001" solref="0.005 1"/>
    <connect anchor="0 0 0" body1="left_follower" body2="left_coupler" solimp="0.95 0.99 0.001" solref="0.005 1"/>
    <joint joint1="right_driver_joint" joint2="left_driver_joint" polycoef="0 1 0 0 0" solimp="0.95 0.99 0.001" solref="0.005 1"/>
  </equality>

  <actuator>
    <position name="joint_x" joint="joint_x" kp="50000" kv="2500"/>
    <position name="joint_y" joint="joint_y" kp="50000" kv="2500"/>
    <position name="joint_th" joint="joint_th" kp="10000" kv="500"/>
    <position class="large_actuator" name="joint_1" joint="joint_1"/>
    <position class="large_actuator" name="joint_2" joint="joint_2" ctrlrange="-2.2497 2.2497"/>
    <position class="large_actuator" name="joint_3" joint="joint_3"/>
    <position class="large_actuator" name="joint_4" joint="joint_4" ctrlrange="-2.5796 2.5796"/>
    <position class="small_actuator" name="joint_5" joint="joint_5"/>
    <position class="small_actuator" name="joint_6" joint="joint_6" ctrlrange="-2.0996 2.0996"/>
    <position class="small_actuator" name="joint_7" joint="joint_7"/>
    <general class="2f85" name="fingers_actuator" tendon="split" forcerange="-5 5" ctrlrange="0 255" gainprm="0.3137 0 0" biasprm="0 -100 -10"/>
  </actuator>
</mujoco>